<?xml version="1.0" ?>
<!-- =================================================================================== -->
<!-- |    This document was autogenerated by xacro from iiwa.config.xacro              | -->
<!-- |    EDITING THIS FILE BY HAND IS NOT RECOMMENDED                                 | -->
<!-- =================================================================================== -->
<!-- Kuka iiwa 7DoF manipulator -->
<robot name="iiwa">
  <material name="gray">
    <color rgba="0.5 0.5 0.5 1.0"/>
  </material>
  <material name="blue">
    <color rgba="0.0 0.0 1.0 1.0"/>
  </material>
  <!-- Added base -->
  <link name="iiwa_base" type="fixed">
    <visual>
      <origin rpy="0 0 0" xyz="0 0 0"/>
      <geometry>
        <mesh filename="package://iiwa_description/meshes/flex_fellow_h800/flex_fellow_h800.dae"/>
      </geometry>
    </visual>
    <collision>
      <origin rpy="0 0 1.570796326795" xyz="0 0 0"/>
      <geometry>
        <mesh filename="package://iiwa_description/meshes/flex_fellow_h800/flex_fellow_h800.stl"/>
      </geometry>
    </collision>
  </link>
  <joint name="iiwa_root_joint" type="fixed">
    <origin rpy="3.14159265359 0.0 0.0" xyz="-0.25 0.0 0.90"/>
    <parent link="world"/>
    <child link="iiwa_base"/>
  </joint>
  <!-- Added table plane-->
  <link name="table_plane">
    <visual>
      <origin rpy="0 0 0" xyz="0 0 0"/>
      <geometry>
        <mesh filename="package://iiwa_description/meshes/table_plane.stl" scale="0.0001 0.0001 0.0001"/>
      </geometry>
    </visual>
    <collision>
      <origin rpy="0 0 0" xyz="0 0 0"/>
      <geometry>
        <mesh filename="package://iiwa_description/meshes/table_plane.stl" scale="0.0001 0.0001 0.0001"/>
      </geometry>
    </collision>
  </link>
  <!-- Joint Between the added base and the table-->
  <joint name="joint_a8" type="fixed">
    <origin rpy="0 0 0" xyz="-0.3 0.31 0.10"/>
    <parent link="iiwa_base"/>
    <child link="table_plane"/>
  </joint>
  <!-- Used for fixing robot -->
  <link name="world"/>
  <gazebo reference="world">
    <static>true</static>
  </gazebo>
  <joint name="robot1_iiwa_base_joint" type="fixed">
    <origin rpy="3.14159265359 0.0 -1.570796327" xyz="0.0 0.0 0.0"/>
    <parent link="iiwa_base"/>
    <child link="robot1_link_0"/>
  </joint>
  <link name="robot1_link_0">
    <visual>
      <origin rpy="0.0 0 0" xyz="0 0 0"/>
      <geometry>
        <mesh filename="package://iiwa_description/meshes/lbr_iiwa_14_r820/visual/base_link.dae"/>
      </geometry>
    </visual>
    <collision>
      <origin rpy="0 0 0" xyz="0 0 0"/>
      <geometry>
        <mesh filename="package://iiwa_description/meshes/lbr_iiwa_14_r820/collision/base_link.stl"/>
      </geometry>
    </collision>
    <inertial>
      <origin rpy="0 0 0" xyz="-0.1 0 0.07"/>
      <mass value="5"/>
      <inertia ixx="0.05" ixy="0" ixz="0" iyy="0.06" iyz="0" izz="0.03"/>
    </inertial>
  </link>
  <link name="robot1_link_1">
    <visual>
      <origin rpy="0 0 0" xyz="0 0 0"/>
      <geometry>
        <mesh filename="package://iiwa_description/meshes/lbr_iiwa_14_r820/visual/link_1.dae"/>
      </geometry>
    </visual>
    <collision>
      <origin rpy="0 0 0" xyz="0 0 0"/>
      <geometry>
        <mesh filename="package://iiwa_description/meshes/lbr_iiwa_14_r820/collision/link_1.stl"/>
      </geometry>
    </collision>
    <inertial>
      <origin rpy="0 0 0" xyz="0 -0.03 0.12"/>
      <mass value="4"/>
      <inertia ixx="0.1" ixy="0" ixz="0" iyy="0.09" iyz="0" izz="0.02"/>
    </inertial>
  </link>
  <link name="robot1_link_2">
    <visual>
      <origin rpy="0 0 0" xyz="0 0 0"/>
      <geometry>
        <mesh filename="package://iiwa_description/meshes/lbr_iiwa_14_r820/visual/link_2.dae"/>
      </geometry>
    </visual>
    <collision>
      <origin rpy="0 0 0" xyz="0 0 0"/>
      <geometry>
        <mesh filename="package://iiwa_description/meshes/lbr_iiwa_14_r820/collision/link_2.stl"/>
      </geometry>
    </collision>
    <inertial>
      <origin rpy="0 0 0" xyz="0.0003 0.059 0.042"/>
      <mass value="4"/>
      <inertia ixx="0.05" ixy="0" ixz="0" iyy="0.018" iyz="0" izz="0.044"/>
    </inertial>
  </link>
  <link name="robot1_link_3">
    <visual>
      <origin rpy="0 0 0" xyz="0 0 0"/>
      <geometry>
        <mesh filename="package://iiwa_description/meshes/lbr_iiwa_14_r820/visual/link_3.dae"/>
      </geometry>
    </visual>
    <collision>
      <origin rpy="0 0 0" xyz="0 0 0"/>
      <geometry>
        <mesh filename="package://iiwa_description/meshes/lbr_iiwa_14_r820/collision/link_3.stl"/>
      </geometry>
    </collision>
    <inertial>
      <origin rpy="0 0 0" xyz="0 0.03 0.13"/>
      <mass value="3"/>
      <inertia ixx="0.08" ixy="0" ixz="0" iyy="0.075" iyz="0" izz="0.01"/>
    </inertial>
  </link>
  <link name="robot1_link_4">
    <visual>
      <origin rpy="0 0 0" xyz="0 0 0"/>
      <geometry>
        <mesh filename="package://iiwa_description/meshes/lbr_iiwa_14_r820/visual/link_4.dae"/>
      </geometry>
    </visual>
    <collision>
      <origin rpy="0 0 0" xyz="0 0 0"/>
      <geometry>
        <mesh filename="package://iiwa_description/meshes/lbr_iiwa_14_r820/collision/link_4.stl"/>
      </geometry>
    </collision>
    <inertial>
      <origin rpy="0 0 0" xyz="0 0.067 0.034"/>
      <mass value="2.7"/>
      <inertia ixx="0.03" ixy="0" ixz="0" iyy="0.01" iyz="0" izz="0.029"/>
    </inertial>
  </link>
  <link name="robot1_link_5">
    <visual>
      <origin rpy="0 0 0" xyz="0 0 0"/>
      <geometry>
        <mesh filename="package://iiwa_description/meshes/lbr_iiwa_14_r820/visual/link_5.dae"/>
      </geometry>
    </visual>
    <collision>
      <origin rpy="0 0 0" xyz="0 0 0"/>
      <geometry>
        <mesh filename="package://iiwa_description/meshes/lbr_iiwa_14_r820/collision/link_5.stl"/>
      </geometry>
    </collision>
    <inertial>
      <origin rpy="0 0 0" xyz="0.0001 0.021 0.076"/>
      <mass value="1.7"/>
      <inertia ixx="0.02" ixy="0" ixz="0" iyy="0.018" iyz="0" izz="0.005"/>
    </inertial>
  </link>
  <link name="robot1_link_6">
    <visual>
      <origin rpy="0 0 0" xyz="0 0 0"/>
      <geometry>
        <mesh filename="package://iiwa_description/meshes/lbr_iiwa_14_r820/visual/link_6.dae"/>
      </geometry>
    </visual>
    <collision>
      <origin rpy="0 0 0" xyz="0 0 0"/>
      <geometry>
        <mesh filename="package://iiwa_description/meshes/lbr_iiwa_14_r820/collision/link_6.stl"/>
      </geometry>
    </collision>
    <inertial>
      <origin rpy="0 0 0" xyz="0 0.0006 0.0004"/>
      <mass value="1.8"/>
      <inertia ixx="0.025" ixy="0" ixz="0" iyy="0.0136" iyz="0" izz="0.0247"/>
    </inertial>
  </link>
  <link name="robot1_link_7">
    <visual>
      <origin rpy="0 0 0" xyz="0 0 0.07"/>
      <material name="gray"/>
      <geometry>
        <mesh filename="package://iiwa_description/meshes/lbr_iiwa_14_r820/visual/link_7_2.stl" scale="0.001 0.001 0.001"/>
      </geometry>
    </visual>
    <collision>
      <origin rpy="0 0 0" xyz="0 0 0.07"/>
      <geometry>
        <mesh filename="package://iiwa_description/meshes/lbr_iiwa_14_r820/collision/link_7_2.stl" scale="0.001 0.001 0.001"/>
      </geometry>
    </collision>
    <inertial>
      <origin rpy="0 0 0" xyz="0 0 0.02"/>
      <mass value="0.42857142857142855"/>
      <!--this is for the MFT Pneumatisch flange-->
      <inertia ixx="0.01" ixy="0" ixz="0" iyy="0.01" iyz="0" izz="0.01"/>
    </inertial>
  </link>
  <!-- Added Gripper Link-->
  <link name="robot1_tool0">
    <visual>
      <origin rpy="0 0 0" xyz="0 0 0"/>
      <geometry>
        <mesh filename="package://iiwa_description/meshes/lbr_iiwa_14_r820/klt_gripper_iiwa_90_deg.stl" scale="0.001 0.001 0.001"/>
      </geometry>
    </visual>
    <collision>
      <origin rpy="0 0 0" xyz="0 0 0"/>
      <geometry>
        <mesh filename="package://iiwa_description/meshes/lbr_iiwa_14_r820/klt_gripper_iiwa_90_deg.stl" scale="0.001 0.001 0.001"/>
      </geometry>
    </collision>
  </link>
  <!-- TCP Link -->
  <link name="robot1_tcp">
    <visual>
      <origin rpy="0 0 0" xyz="0 0 0"/>
      <material name="blue"/>
      <geometry>
        <sphere radius="0.01"/>
      </geometry>
    </visual>
    <collision>
      <origin rpy="0 0 0" xyz="0 0 0"/>
      <geometry>
        <sphere radius="0.01"/>
      </geometry>
    </collision>
  </link>
  <joint name="robot1_joint_a1" type="revolute">
    <origin rpy="0 0 0" xyz="0 0 0"/>
    <parent link="robot1_link_0"/>
    <child link="robot1_link_1"/>
    <axis xyz="0 0 1"/>
    <limit effort="320" lower="-2.9668" upper="2.9668" velocity="1.4834"/>
  </joint>
  <joint name="robot1_joint_a2" type="revolute">
    <origin rpy="0 -1.0471975511966667 0" xyz="-0.00043624 0 0.36"/>
    <parent link="robot1_link_1"/>
    <child link="robot1_link_2"/>
    <axis xyz="0 1 0"/>
    <limit effort="320" lower="-2.0942" upper="2.0942" velocity="1.4834"/>
  </joint>
  <joint name="robot1_joint_a3" type="revolute">
    <origin rpy="0 0 0" xyz="0 0 0"/>
    <parent link="robot1_link_2"/>
    <child link="robot1_link_3"/>
    <axis xyz="0 0 1"/>
    <limit effort="176" lower="-2.9668" upper="2.9668" velocity="1.7452"/>
  </joint>
  <joint name="robot1_joint_a4" type="revolute">
    <origin rpy="0 -1.570796326795 0" xyz="0.00043624 0 0.42"/>
    <parent link="robot1_link_3"/>
    <child link="robot1_link_4"/>
    <axis xyz="0 -1 0"/>
    <limit effort="176" lower="-2.0942" upper="2.0942" velocity="1.3089"/>
  </joint>
  <joint name="robot1_joint_a5" type="revolute">
    <origin rpy="0 0 0" xyz="0 0 0"/>
    <parent link="robot1_link_4"/>
    <child link="robot1_link_5"/>
    <axis xyz="0 0 1"/>
    <limit effort="110" lower="-2.9668" upper="2.9668" velocity="2.2688"/>
  </joint>
  <joint name="robot1_joint_a6" type="revolute">
    <origin rpy="0 -0.5235987755983333 0" xyz="0 0 0.4"/>
    <parent link="robot1_link_5"/>
    <child link="robot1_link_6"/>
    <axis xyz="0 1 0"/>
    <limit effort="40" lower="-2.0942" upper="2.0942" velocity="2.356"/>
  </joint>
  <joint name="robot1_joint_a7" type="revolute">
    <origin rpy="0 0 0" xyz="0 0 0"/>
    <parent link="robot1_link_6"/>
    <child link="robot1_link_7"/>
    <axis xyz="0 0 1"/>
    <limit effort="40" lower="-3.0541" upper="3.0541" velocity="2.356"/>
  </joint>
  <joint name="robot1_joint_a7-tool0" type="fixed">
    <origin rpy="0 1.570796326795 1.570796326795" xyz="0 -0.06 0.205"/>
    <parent link="robot1_link_7"/>
    <child link="robot1_tool0"/>
    <axis xyz="0 0 0"/>
  </joint>
  <joint name="robot1_tcp_joint" type="fixed">
    <origin rpy="0.0 3.14159265359 0" xyz="-0.05 0.0 0.0"/>
    <parent link="robot1_tool0"/>
    <child link="robot1_tcp"/>
  </joint>
  <joint name="robot2_iiwa_base_joint" type="fixed">
    <origin rpy="3.14159265359 0.0 1.570796327" xyz="0.52 0.0 0.0"/>
    <parent link="iiwa_base"/>
    <child link="robot2_link_0"/>
  </joint>
  <link name="robot2_link_0">
    <visual>
      <origin rpy="0.0 0 0" xyz="0 0 0"/>
      <geometry>
        <mesh filename="package://iiwa_description/meshes/lbr_iiwa_14_r820/visual/base_link.dae"/>
      </geometry>
    </visual>
    <collision>
      <origin rpy="0 0 0" xyz="0 0 0"/>
      <geometry>
        <mesh filename="package://iiwa_description/meshes/lbr_iiwa_14_r820/collision/base_link.stl"/>
      </geometry>
    </collision>
    <inertial>
      <origin rpy="0 0 0" xyz="-0.1 0 0.07"/>
      <mass value="5"/>
      <inertia ixx="0.05" ixy="0" ixz="0" iyy="0.06" iyz="0" izz="0.03"/>
    </inertial>
  </link>
  <link name="robot2_link_1">
    <visual>
      <origin rpy="0 0 0" xyz="0 0 0"/>
      <geometry>
        <mesh filename="package://iiwa_description/meshes/lbr_iiwa_14_r820/visual/link_1.dae"/>
      </geometry>
    </visual>
    <collision>
      <origin rpy="0 0 0" xyz="0 0 0"/>
      <geometry>
        <mesh filename="package://iiwa_description/meshes/lbr_iiwa_14_r820/collision/link_1.stl"/>
      </geometry>
    </collision>
    <inertial>
      <origin rpy="0 0 0" xyz="0 -0.03 0.12"/>
      <mass value="4"/>
      <inertia ixx="0.1" ixy="0" ixz="0" iyy="0.09" iyz="0" izz="0.02"/>
    </inertial>
  </link>
  <link name="robot2_link_2">
    <visual>
      <origin rpy="0 0 0" xyz="0 0 0"/>
      <geometry>
        <mesh filename="package://iiwa_description/meshes/lbr_iiwa_14_r820/visual/link_2.dae"/>
      </geometry>
    </visual>
    <collision>
      <origin rpy="0 0 0" xyz="0 0 0"/>
      <geometry>
        <mesh filename="package://iiwa_description/meshes/lbr_iiwa_14_r820/collision/link_2.stl"/>
      </geometry>
    </collision>
    <inertial>
      <origin rpy="0 0 0" xyz="0.0003 0.059 0.042"/>
      <mass value="4"/>
      <inertia ixx="0.05" ixy="0" ixz="0" iyy="0.018" iyz="0" izz="0.044"/>
    </inertial>
  </link>
  <link name="robot2_link_3">
    <visual>
      <origin rpy="0 0 0" xyz="0 0 0"/>
      <geometry>
        <mesh filename="package://iiwa_description/meshes/lbr_iiwa_14_r820/visual/link_3.dae"/>
      </geometry>
    </visual>
    <collision>
      <origin rpy="0 0 0" xyz="0 0 0"/>
      <geometry>
        <mesh filename="package://iiwa_description/meshes/lbr_iiwa_14_r820/collision/link_3.stl"/>
      </geometry>
    </collision>
    <inertial>
      <origin rpy="0 0 0" xyz="0 0.03 0.13"/>
      <mass value="3"/>
      <inertia ixx="0.08" ixy="0" ixz="0" iyy="0.075" iyz="0" izz="0.01"/>
    </inertial>
  </link>
  <link name="robot2_link_4">
    <visual>
      <origin rpy="0 0 0" xyz="0 0 0"/>
      <geometry>
        <mesh filename="package://iiwa_description/meshes/lbr_iiwa_14_r820/visual/link_4.dae"/>
      </geometry>
    </visual>
    <collision>
      <origin rpy="0 0 0" xyz="0 0 0"/>
      <geometry>
        <mesh filename="package://iiwa_description/meshes/lbr_iiwa_14_r820/collision/link_4.stl"/>
      </geometry>
    </collision>
    <inertial>
      <origin rpy="0 0 0" xyz="0 0.067 0.034"/>
      <mass value="2.7"/>
      <inertia ixx="0.03" ixy="0" ixz="0" iyy="0.01" iyz="0" izz="0.029"/>
    </inertial>
  </link>
  <link name="robot2_link_5">
    <visual>
      <origin rpy="0 0 0" xyz="0 0 0"/>
      <geometry>
        <mesh filename="package://iiwa_description/meshes/lbr_iiwa_14_r820/visual/link_5.dae"/>
      </geometry>
    </visual>
    <collision>
      <origin rpy="0 0 0" xyz="0 0 0"/>
      <geometry>
        <mesh filename="package://iiwa_description/meshes/lbr_iiwa_14_r820/collision/link_5.stl"/>
      </geometry>
    </collision>
    <inertial>
      <origin rpy="0 0 0" xyz="0.0001 0.021 0.076"/>
      <mass value="1.7"/>
      <inertia ixx="0.02" ixy="0" ixz="0" iyy="0.018" iyz="0" izz="0.005"/>
    </inertial>
  </link>
  <link name="robot2_link_6">
    <visual>
      <origin rpy="0 0 0" xyz="0 0 0"/>
      <geometry>
        <mesh filename="package://iiwa_description/meshes/lbr_iiwa_14_r820/visual/link_6.dae"/>
      </geometry>
    </visual>
    <collision>
      <origin rpy="0 0 0" xyz="0 0 0"/>
      <geometry>
        <mesh filename="package://iiwa_description/meshes/lbr_iiwa_14_r820/collision/link_6.stl"/>
      </geometry>
    </collision>
    <inertial>
      <origin rpy="0 0 0" xyz="0 0.0006 0.0004"/>
      <mass value="1.8"/>
      <inertia ixx="0.025" ixy="0" ixz="0" iyy="0.0136" iyz="0" izz="0.0247"/>
    </inertial>
  </link>
  <link name="robot2_link_7">
    <visual>
      <origin rpy="0 0 0" xyz="0 0 0.07"/>
      <material name="gray"/>
      <geometry>
        <mesh filename="package://iiwa_description/meshes/lbr_iiwa_14_r820/visual/link_7_2.stl" scale="0.001 0.001 0.001"/>
      </geometry>
    </visual>
    <collision>
      <origin rpy="0 0 0" xyz="0 0 0.07"/>
      <geometry>
        <mesh filename="package://iiwa_description/meshes/lbr_iiwa_14_r820/collision/link_7_2.stl" scale="0.001 0.001 0.001"/>
      </geometry>
    </collision>
    <inertial>
      <origin rpy="0 0 0" xyz="0 0 0.02"/>
      <mass value="0.42857142857142855"/>
      <!--this is for the MFT Pneumatisch flange-->
      <inertia ixx="0.01" ixy="0" ixz="0" iyy="0.01" iyz="0" izz="0.01"/>
    </inertial>
  </link>
  <!-- Added Gripper Link-->
  <link name="robot2_tool0">
    <visual>
      <origin rpy="0 0 0" xyz="0 0 0"/>
      <geometry>
        <mesh filename="package://iiwa_description/meshes/lbr_iiwa_14_r820/klt_gripper_iiwa_90_deg.stl" scale="0.001 0.001 0.001"/>
      </geometry>
    </visual>
    <collision>
      <origin rpy="0 0 0" xyz="0 0 0"/>
      <geometry>
        <mesh filename="package://iiwa_description/meshes/lbr_iiwa_14_r820/klt_gripper_iiwa_90_deg.stl" scale="0.001 0.001 0.001"/>
      </geometry>
    </collision>
  </link>
  <!-- TCP Link -->
  <link name="robot2_tcp">
    <visual>
      <origin rpy="0 0 0" xyz="0 0 0"/>
      <material name="blue"/>
      <geometry>
        <sphere radius="0.01"/>
      </geometry>
    </visual>
    <collision>
      <origin rpy="0 0 0" xyz="0 0 0"/>
      <geometry>
        <sphere radius="0.01"/>
      </geometry>
    </collision>
  </link>
  <joint name="robot2_joint_a1" type="revolute">
    <origin rpy="0 0 0" xyz="0 0 0"/>
    <parent link="robot2_link_0"/>
    <child link="robot2_link_1"/>
    <axis xyz="0 0 1"/>
    <limit effort="320" lower="-2.9668" upper="2.9668" velocity="1.4834"/>
  </joint>
  <joint name="robot2_joint_a2" type="revolute">
    <origin rpy="0 1.0471975511966667 0" xyz="-0.00043624 0 0.36"/>
    <parent link="robot2_link_1"/>
    <child link="robot2_link_2"/>
    <axis xyz="0 1 0"/>
    <limit effort="320" lower="-2.0942" upper="2.0942" velocity="1.4834"/>
  </joint>
  <joint name="robot2_joint_a3" type="revolute">
    <origin rpy="0 0 0" xyz="0 0 0"/>
    <parent link="robot2_link_2"/>
    <child link="robot2_link_3"/>
    <axis xyz="0 0 1"/>
    <limit effort="176" lower="-2.9668" upper="2.9668" velocity="1.7452"/>
  </joint>
  <joint name="robot2_joint_a4" type="revolute">
    <origin rpy="0 1.570796326795 0" xyz="0.00043624 0 0.42"/>
    <parent link="robot2_link_3"/>
    <child link="robot2_link_4"/>
    <axis xyz="0 -1 0"/>
    <limit effort="176" lower="-2.0942" upper="2.0942" velocity="1.3089"/>
  </joint>
  <joint name="robot2_joint_a5" type="revolute">
    <origin rpy="0 0 0" xyz="0 0 0"/>
    <parent link="robot2_link_4"/>
    <child link="robot2_link_5"/>
    <axis xyz="0 0 1"/>
    <limit effort="110" lower="-2.9668" upper="2.9668" velocity="2.2688"/>
  </joint>
  <joint name="robot2_joint_a6" type="revolute">
    <origin rpy="0 0.5235987755983333 0" xyz="0 0 0.4"/>
    <parent link="robot2_link_5"/>
    <child link="robot2_link_6"/>
    <axis xyz="0 1 0"/>
    <limit effort="40" lower="-2.0942" upper="2.0942" velocity="2.356"/>
  </joint>
  <joint name="robot2_joint_a7" type="revolute">
    <origin rpy="0 0 0" xyz="0 0 0"/>
    <parent link="robot2_link_6"/>
    <child link="robot2_link_7"/>
    <axis xyz="0 0 1"/>
    <limit effort="40" lower="-3.0541" upper="3.0541" velocity="2.356"/>
  </joint>
  <joint name="robot2_joint_a7-tool0" type="fixed">
    <origin rpy="0 1.570796326795 1.570796326795" xyz="0 -0.06 0.205"/>
    <parent link="robot2_link_7"/>
    <child link="robot2_tool0"/>
    <axis xyz="0 0 0"/>
  </joint>
  <joint name="robot2_tcp_joint" type="fixed">
    <origin rpy="0.0 3.14159265359 0" xyz="-0.05 0.0 0.0"/>
    <parent link="robot2_tool0"/>
    <child link="robot2_tcp"/>
  </joint>
  <ros2_control name="robot1_iiwaRobot" type="system">
    <hardware>
      <plugin>fake_components/GenericSystem</plugin>
      <param name="state_following_offset">0.0</param>
    </hardware>
    <joint name="robot1_joint_a1">
      <command_interface name="position"/>
      <param name="min">-2.96</param>
      <param name="max">2.96</param>
      <state_interface name="position">
        <param name="initial_value">0.0</param>
      </state_interface>
      <state_interface name="velocity">
        <param name="initial_value">0.0</param>
      </state_interface>
      <state_interface name="effort">
        <param name="initial_value">0.0</param>
      </state_interface>
    </joint>
    <joint name="robot1_joint_a2">
      <command_interface name="position"/>
      <param name="min">-2.09</param>
      <param name="max">2.09</param>
      <state_interface name="position">
        <param name="initial_value">0.0</param>
      </state_interface>
      <state_interface name="velocity">
        <param name="initial_value">0.0</param>
      </state_interface>
      <state_interface name="effort">
        <param name="initial_value">0.0</param>
      </state_interface>
    </joint>
    <joint name="robot1_joint_a3">
      <command_interface name="position"/>
      <param name="min">-2.96</param>
      <param name="max">2.96</param>
      <state_interface name="position">
        <param name="initial_value">0.0</param>
      </state_interface>
      <state_interface name="velocity">
        <param name="initial_value">0.0</param>
      </state_interface>
      <state_interface name="effort">
        <param name="initial_value">0.0</param>
      </state_interface>
    </joint>
    <joint name="robot1_joint_a4">
      <command_interface name="position"/>
      <param name="min">-2.09</param>
      <param name="max">2.09</param>
      <state_interface name="position">
        <param name="initial_value">0.0</param>
      </state_interface>
      <state_interface name="velocity">
        <param name="initial_value">0.0</param>
      </state_interface>
      <state_interface name="effort">
        <param name="initial_value">0.0</param>
      </state_interface>
    </joint>
    <joint name="robot1_joint_a5">
      <command_interface name="position"/>
      <param name="min">-2.96</param>
      <param name="max">2.96</param>
      <state_interface name="position">
        <param name="initial_value">0.0</param>
      </state_interface>
      <state_interface name="velocity">
        <param name="initial_value">0.0</param>
      </state_interface>
      <state_interface name="effort">
        <param name="initial_value">0.0</param>
      </state_interface>
    </joint>
    <joint name="robot1_joint_a6">
      <command_interface name="position"/>
      <param name="min">-2.09</param>
      <param name="max">2.09</param>
      <state_interface name="position">
        <param name="initial_value">0.0</param>
      </state_interface>
      <state_interface name="velocity">
        <param name="initial_value">0.0</param>
      </state_interface>
      <state_interface name="effort">
        <param name="initial_value">0.0</param>
      </state_interface>
    </joint>
    <joint name="robot1_joint_a7">
      <command_interface name="position"/>
      <param name="min">-3.05</param>
      <param name="max">3.05</param>
      <state_interface name="position">
        <param name="initial_value">0.0</param>
      </state_interface>
      <state_interface name="velocity">
        <param name="initial_value">0.0</param>
      </state_interface>
      <state_interface name="effort">
        <param name="initial_value">0.0</param>
      </state_interface>
    </joint>
    <sensor name="robot1_external_torque_sensor">
      <state_interface name="external_torque.{prefix}joint_a1"/>
      <state_interface name="external_torque.{prefix}joint_a2"/>
      <state_interface name="external_torque.{prefix}joint_a3"/>
      <state_interface name="external_torque.{prefix}joint_a4"/>
      <state_interface name="external_torque.{prefix}joint_a5"/>
      <state_interface name="external_torque.{prefix}joint_a6"/>
      <state_interface name="external_torque.{prefix}joint_a7"/>
    </sensor>
  </ros2_control>
  <ros2_control name="robot2_iiwaRobot" type="system">
    <hardware>
      <plugin>fake_components/GenericSystem</plugin>
      <param name="state_following_offset">0.0</param>
    </hardware>
    <joint name="robot2_joint_a1">
      <command_interface name="position"/>
      <param name="min">-2.96</param>
      <param name="max">2.96</param>
      <state_interface name="position">
        <param name="initial_value">0.0</param>
      </state_interface>
      <state_interface name="velocity">
        <param name="initial_value">0.0</param>
      </state_interface>
      <state_interface name="effort">
        <param name="initial_value">0.0</param>
      </state_interface>
    </joint>
    <joint name="robot2_joint_a2">
      <command_interface name="position"/>
      <param name="min">-2.09</param>
      <param name="max">2.09</param>
      <state_interface name="position">
        <param name="initial_value">0.0</param>
      </state_interface>
      <state_interface name="velocity">
        <param name="initial_value">0.0</param>
      </state_interface>
      <state_interface name="effort">
        <param name="initial_value">0.0</param>
      </state_interface>
    </joint>
    <joint name="robot2_joint_a3">
      <command_interface name="position"/>
      <param name="min">-2.96</param>
      <param name="max">2.96</param>
      <state_interface name="position">
        <param name="initial_value">0.0</param>
      </state_interface>
      <state_interface name="velocity">
        <param name="initial_value">0.0</param>
      </state_interface>
      <state_interface name="effort">
        <param name="initial_value">0.0</param>
      </state_interface>
    </joint>
    <joint name="robot2_joint_a4">
      <command_interface name="position"/>
      <param name="min">-2.09</param>
      <param name="max">2.09</param>
      <state_interface name="position">
        <param name="initial_value">0.0</param>
      </state_interface>
      <state_interface name="velocity">
        <param name="initial_value">0.0</param>
      </state_interface>
      <state_interface name="effort">
        <param name="initial_value">0.0</param>
      </state_interface>
    </joint>
    <joint name="robot2_joint_a5">
      <command_interface name="position"/>
      <param name="min">-2.96</param>
      <param name="max">2.96</param>
      <state_interface name="position">
        <param name="initial_value">0.0</param>
      </state_interface>
      <state_interface name="velocity">
        <param name="initial_value">0.0</param>
      </state_interface>
      <state_interface name="effort">
        <param name="initial_value">0.0</param>
      </state_interface>
    </joint>
    <joint name="robot2_joint_a6">
      <command_interface name="position"/>
      <param name="min">-2.09</param>
      <param name="max">2.09</param>
      <state_interface name="position">
        <param name="initial_value">0.0</param>
      </state_interface>
      <state_interface name="velocity">
        <param name="initial_value">0.0</param>
      </state_interface>
      <state_interface name="effort">
        <param name="initial_value">0.0</param>
      </state_interface>
    </joint>
    <joint name="robot2_joint_a7">
      <command_interface name="position"/>
      <param name="min">-3.05</param>
      <param name="max">3.05</param>
      <state_interface name="position">
        <param name="initial_value">0.0</param>
      </state_interface>
      <state_interface name="velocity">
        <param name="initial_value">0.0</param>
      </state_interface>
      <state_interface name="effort">
        <param name="initial_value">0.0</param>
      </state_interface>
    </joint>
    <sensor name="robot2_external_torque_sensor">
      <state_interface name="external_torque.{prefix}joint_a1"/>
      <state_interface name="external_torque.{prefix}joint_a2"/>
      <state_interface name="external_torque.{prefix}joint_a3"/>
      <state_interface name="external_torque.{prefix}joint_a4"/>
      <state_interface name="external_torque.{prefix}joint_a5"/>
      <state_interface name="external_torque.{prefix}joint_a6"/>
      <state_interface name="external_torque.{prefix}joint_a7"/>
    </sensor>
  </ros2_control>
  <!-- ros_control plugin -->
  <gazebo>
    <plugin filename="libgazebo_ros2_control.so" name="gazebo_ros2_control">
      <parameters>/home/newtonjeri/Franks_Project/project_ws/install/iiwa_description/share/iiwa_description/config/iiwa_controllers.yaml</parameters>
    </plugin>
  </gazebo>
  <!-- color -->
  <gazebo reference="robot1_link_7">
    <material>Gazebo/Gray</material>
  </gazebo>
  <!-- ros_control plugin -->
  <gazebo>
    <plugin filename="libgazebo_ros2_control.so" name="gazebo_ros2_control">
      <parameters>/home/newtonjeri/Franks_Project/project_ws/install/iiwa_description/share/iiwa_description/config/iiwa_controllers.yaml</parameters>
    </plugin>
  </gazebo>
  <!-- color -->
  <gazebo reference="robot2_link_7">
    <material>Gazebo/Gray</material>
  </gazebo>
</robot>
